<?xml version="1.0" encoding="UTF-8"?>
<testsuite name="cuenta_pend_facturarV2-20241029164123" tests="1" file=".py" time="32.440" timestamp="2024-10-29T16:41:55" failures="0" errors="1" skipped="0">
	<testcase classname="cuenta_pend_facturarV2" name="test_pend_facturarV2" time="32.440" timestamp="2024-10-29T16:41:55" file="ReportPendFactV2.py" line="20">
		<error type="TimeoutException" message="Message: 
"><![CDATA[Traceback (most recent call last):
  File "c:\Users\luist\repos\Automatizaciones_M-dulos-\ReportPendFactV2.py", line 44, in test_pend_facturarV2
    calendar_todate_retro(self.driver, select_calendar, popup_xpath, select_chevron, popup_xpath2, clicks=click_chevron)
  File "c:\Users\luist\repos\Automatizaciones_M-dulos-\Elements.py", line 1485, in calendar_todate_retro
    input_fecha = WebDriverWait(driver, 10).until(
  File "C:\Users\luist\AppData\Roaming\Python\Python310\site-packages\selenium\webdriver\support\wait.py", line 105, in until
    raise TimeoutException(message, screen, stacktrace)
selenium.common.exceptions.TimeoutException: Message: 

]]></error>
	</testcase>
</testsuite>
