<?xml version="1.0" encoding="UTF-8"?>
<testsuite name="finanzaspagos-20240716114622" tests="1" file=".py" time="90.371" timestamp="2024-07-16T11:47:52" failures="0" errors="1" skipped="0">
	<testcase classname="finanzaspagos" name="test_finance_payment" time="90.371" timestamp="2024-07-16T11:47:52" file="finanzasPagos.py" line="22">
		<error type="AttributeError" message="module 'datetime' has no attribute 'now'"><![CDATA[Traceback (most recent call last):
  File "c:\Users\luist\repos\Automatizaciones-SILOHUB-\finanzasPagos.py", line 123, in test_finance_payment
    verify_todate(self.driver,select_todate)
  File "c:\Users\luist\repos\Automatizaciones-SILOHUB-\Elements.py", line 1622, in verify_todate
    fecha_actual = datetime.now().strftime('%Y-%m-%d')
AttributeError: module 'datetime' has no attribute 'now'
]]></error>
		<system-out><![CDATA[Tiempo de espera agotado. El texto por xpaht no está presente.
¡Input encontrado y enviado con éxito!
]]></system-out>
	</testcase>
</testsuite>
