<?xml version="1.0" encoding="UTF-8"?>
<testsuite name="ctacte_PesiFechaComproV2.cta_cte_pesiFechaComproV2-failed" tests="1" file="ctacte_PesiFechaComproV2.py" time="6.210" timestamp="2024-11-06T14:35:33" failures="0" errors="1" skipped="0">
	<testcase classname="ctacte_PesiFechaComproV2.cta_cte_pesiFechaComproV2" name="test_ctacte_Date_expiration" time="6.210" timestamp="2024-11-06T14:35:33" file="ctacte_PesiFechaComproV2.py" line="18">
		<error type="WebDriverException" message="Message: Process unexpectedly closed with status 0
"><![CDATA[Traceback (most recent call last):
  File "c:\Users\luist\repos\Automatizaciones_M-dulos-\ctacte_PesiFechaComproV2.py", line 12, in setUp
    self.start_session = StartSessionFirefox()
  File "c:\Users\luist\repos\Automatizaciones_M-dulos-\StartSessionFirefox.py", line 18, in __init__
    self.driver = webdriver.Firefox(options=firefox_options)
  File "C:\Users\luist\AppData\Roaming\Python\Python310\site-packages\selenium\webdriver\firefox\webdriver.py", line 71, in __init__
    super().__init__(command_executor=executor, options=options)
  File "C:\Users\luist\AppData\Roaming\Python\Python310\site-packages\selenium\webdriver\remote\webdriver.py", line 212, in __init__
    self.start_session(capabilities)
  File "C:\Users\luist\AppData\Roaming\Python\Python310\site-packages\selenium\webdriver\remote\webdriver.py", line 299, in start_session
    response = self.execute(Command.NEW_SESSION, caps)["value"]
  File "C:\Users\luist\AppData\Roaming\Python\Python310\site-packages\selenium\webdriver\remote\webdriver.py", line 354, in execute
    self.error_handler.check_response(response)
  File "C:\Users\luist\AppData\Roaming\Python\Python310\site-packages\selenium\webdriver\remote\errorhandler.py", line 229, in check_response
    raise exception_class(message, screen, stacktrace)
selenium.common.exceptions.WebDriverException: Message: Process unexpectedly closed with status 0

]]></error>
	</testcase>
</testsuite>
