<?xml version="1.0" encoding="UTF-8"?>
<testsuite name="Metricas-20240318184041" tests="1" file=".py" time="25.734" timestamp="2024-03-18T18:41:07" failures="0" errors="1" skipped="0">
	<testcase classname="Metricas" name="test_metricas" time="25.734" timestamp="2024-03-18T18:41:07" file="Metricas.py" line="18">
		<error type="TimeoutException" message="Message: 
"><![CDATA[Traceback (most recent call last):
  File "c:\Users\luist\repos\Automatizaciones-SILOHUB-\Metricas.py", line 21, in test_metricas
    self.login_helper.select_tenant()
  File "c:\Users\luist\repos\Automatizaciones-SILOHUB-\loginhelper.py", line 19, in select_tenant
    select_tenant = find_element_by_xpath(self.driver, "/html/body/app-root/app-layout/app-vertical/div/div/div/div/app-home-main/div/div[1]/app-tenant-main/app-tenant[8]/div/div/img")
  File "c:\Users\luist\repos\Automatizaciones-SILOHUB-\FindElements.py", line 14, in find_element_by_xpath
    return WebDriverWait(driver, 10).until(EC.presence_of_element_located((By.XPATH, xpath)))
  File "C:\Users\luist\AppData\Roaming\Python\Python310\site-packages\selenium\webdriver\support\wait.py", line 105, in until
    raise TimeoutException(message, screen, stacktrace)
selenium.common.exceptions.TimeoutException: Message: 

]]></error>
	</testcase>
</testsuite>
